Workbook

Sheet Infos du site
A1: code INSPIRE (https://inpn.mnhn.fr/accueil/index) | B1: Nom du site | C1: Statut du site | D1: Superficie (ha) | E1: Profil du site | F1: Organisme(s) gestionnaire(s) | G1: Département(s) | H1: Date fin DAT | I1: Nom du contributeur | J1: Type de contrat et durée
A2: FR.MNHN.I056FR3600174 | B2: Casse de la Belle Henriette | C2: Réserve naturelle nationale | D2: 337 | E2: Lagune ; Périurbain ; ornithologique ; | F2: LPO France ; OFB | G2: 85 | H2: 44804 | I2: MARECHAL Anatole | J2: CDI
B13: Document mis à disposition sous un contrat Creative Commons CC BY-NC-ND (4.0) https://creativecommons.org/licenses/by-nc-nd/4.0/

Sheet Acteurs
A1: Numéro d'anonymisation des acteurs | B1: Membres du CCG (groupe1) | C1: Partenaires, gestionnaires et techniciens (groupe2) | D1: Animation, découverte de l'environnement, tourisme (groupe3) | E1: Riverains, élus et usagers locaux (groupe4) | F1: Acteurs économiques (groupe 5) | G1: Nom | H1: Prénom | I1: Age | J1: Statut | K1: Structure | L1: Tel | M1: Mail | N1: Date entretien | O1: Contexte entretien | P1: Profil Cognitif
A2: Acteur1 | B2: 1 | E2: 1 | G2: James | H2: Jessie | I2: 40 | J2: Directrice | K2: Syndicat Mixte | L2: 00.00.00.00.00 | M2: jessie.james@syndicat.com | N2: XX/XX/XX | O2: langue de bois | P2: Territorial
A3: Acteur2 | C3: 1 | G3: Genty | H3: Bobby | I3: 51 | J3: Agent municipal | K3: Commune Trifouilly les oies | L3: 00.00.00.00.00 | M3: bobby@trifouillylesoies.com | N3: XX/XX/XX | O3: convivial | P3: Fédérateur
A4: …
B8: Document mis à disposition sous un contrat Creative Commons CC BY-NC-ND (4.0) https://creativecommons.org/licenses/by-nc-nd/4.0/

Sheet Formulaire
B1: CONNAISSANCE | C1: CONNAISSANCE | D1: CONNAISSANCE | E1: CONNAISSANCE | F1: CONNAISSANCE | G1: CONNAISSANCE | H1: CONNAISSANCE | I1: CONNAISSANCE | J1: CONNAISSANCE | K1: CONNAISSANCE | L1: INTERET | M1: INTERET | N1: INTERET | O1: INTERET | P1: INTERET | Q1: INTERET | R1: INTERET | S1: INTERET | T1: INTERET | U1: IMPLICATION | V1: IMPLICATION | W1: IMPLICATION | X1: IMPLICATION | Y1: IMPLICATION | Z1: IMPLICATION | AA1: métrique complémentaire : CCG | AE1: Conclusion
A2: N° de la métrique | B2: 1 | C2: 2 | D2: 3 | E2: 4 | F2: 5 | G2: 6 | H2: 7 | I2: 8 | J2: 9 | K2: 10 | L2: 11 | M2: 12 | N2: 13 | O2: 14 | P2: 15 | Q2: 16 | R2: 17 | S2: 18 | T2: 19 | U2: 20 | V2: 21 | W2: 22 | X2: 23 | Y2: 24 | Z2: 25 | AA2: 26 | AB2: 27 | AC2: 28 | AD2: 29 | AE2: 30 | AF2: 31 | AG2: 32
A3: Titre de la métrique | B3: Missions | C3: Actions | D3: Animations | E3: Organisme(s) gestionnaire(s) | F3: Périmètre | G3: Règlementation | H3: Espèces représentatives | I3: Outils de communication présentés | J3: Interlocuteurs pour s'informer | K3: Accessibilité à l'infos | L3: Fréquence des visites | M3: Avis sur les animations | N3: Avis sur la Règlementation | O3: Avis sur l'existence | P3: Avis sur l'efficacité des actions | Q3: Avis organisme(s) gestionnaire(s) | R3: Avis sur la plus-value de la réserve | S3: Avis sur les contraintes | T3: Evolution des avis | U3: Nature des liens | V3: Importance des liens | W3: Participation animations | X3: Impression d'être consulté | Y3: Qualité des échanges | Z3: Evolution des échanges | AA3: Implication CCG | AB3: Avis CCG | AC3: Interventions CCG | AD3: Participation CCG | AE3: Attentes | AF3: Synthèse | AG3: Enracinement
A4: Définition de la métrique | B4: Niveau de connaissance des missions d'une RN en général | C4: Niveau de connaissance des champs d'action de la RN | D4: Niveau de connaissance des animations proposées par la réserve | E4: Niveau de connaissance du gestionnaire de la réserve | F4: Niveau de connaissance réel du périmètre du site | G4: Niveau de connaissance de la règlementation de la RN | H4: Niveau de connaissance des espèces représentatives de la RN | I4: Niveau de connaissance des outils de communication présentés lors de l'entretien | J4: Niveau de connaissance des interlocuteurs de la RN | K4: Niveau d'accessibilité des informations et actualités sur la RN | L4: Fréquentation du site par les acteurs locaux | M4: Evaluation de l'avis sur les animations | N4: Evaluation de l'avis sur la règlementation | O4: Evaluation de l'avis sur l'existence de la réserve | P4: Evaluation de l'avis sur l'efficacité des actions | Q4: Evaluation de l'avis sur l'organisme gestionnaire | R4: Evaluation de la plus-value de la réserve | S4: Evaluation des contraintes induites par la RN | T4: Evaluation de l'évolutiondes avis à l'égard de la RN | U4: Evaluation de la nature des liens entre acteurs et RN | V4: Evaluation de l'importance des liens | W4: Evaluation de la participation aux animations | X4: Evaluation du sentiment de consultation sur des sujets qui concernent l'enquêté | Y4: Evaluation du ressenti de la qualité des rapports humains avec l'équipe de la RN. | Z4: Evaluation de l'évolution des échanges avec l'équipe de la réserve | AA4: Evaluation du sentiment d'implication | AB4: Ressenti d'intérêt vis-à-vis de cette instance | AC4: Evaluation de la fréquence d'interventions | AD4: Evaluation de la fréquence de participation
A5: Question liée à la métrique dans la trame d'entretien | B5: Selon-vous, quelles sont les missions d'une réserve naturelle, en général ? | C5: Concrètement, savez-vous ce qui se fait sur cette réserve ? | D5: Connaissez-vous des animations proposées par la réserve et lesquelles ? | E5: Connaissez vous les organismes gestionnaires de la réserve ? | F5: Voulez-vous bien tracer le périmètre de la réserve sur une carte ? | G5: Connaissez-vous des règles à respecter sur la réserve ? | H5: Selon vous, quelles sont les espèces représentatives de la réserve ? | I5: Parmi les documents suivants, lesquels connaissez-vous ? | J5: Vers qui vous tournez vous pour avoir des informations ? | K5: Les informations sur la RN sont elles accessibles ? | L5: A quelle fréquence venez-vous voir la réserve pour des raisons professionnelles ou de loisirs ? | M5: Quel est votre avis sur les animations ? | N5: Quel est votre avis sur la réglementation ? | O5: Est-ce que vous êtes d’accord avec l’existence de la réserve ici ? | P5: Pensez-vous que ces actions soient globalement efficaces ? | Q5: Quel est votre avis sur l’organisme gestionnaire ? | R5: La réserve représente-elle une/des plus-values pour vous ? | S5: La réserve représente-t-elle des contraintes pour vous ? | T5: Avec le temps et globalement, est-ce que votre avis sur la réserve a évolué ? | U5: Pouvez-vous citer tous les liens qui existent entre vous et la réserve ? Et pouvez-vous nous en dire plus leur nature ? | V5: Pouvez-vous qualifier globalement l’importance de ces liens ? | W5: Avez-vous l'habitude de participer à des activités / événements / vernissages / animations / points d'observations… organisées par la RN ? | X5: Vous sentez-vous consulté par la RN sur les sujets qui vous concernent ? | Y5: Concernant l’équipe de gestion du site, comment se passent vos échanges ? | Z5: Ces échanges ont-ils évolué avec le temps ? | AA5: En tant que membre du CCG, avez-vous l'impression d'être impliqué dans la vie de la RN | AB5: Que pensez-vous du CCG, en tant qu’instance de discussion ? | AC5: Lors du CCG, faites-vous des interventions régulièrement (questions, prises de positions) | AD5: Quelle est la fréquence de votre participation au CCG ? | AE5: Avez-vous des attentes particulières par rapport à la RN ? | AF5: Pour faire la synthèse de tous les points abordés précédemment, la RN apporte-t-elle dans l’ensemble plutôt des bénéfices ou des inconvénients sur ce territoire ? | AG5: Selon vous, la réserve est-elle bien enracinée sur le territoire ? Pourquoi ?
A6: Réponse attendue à la métrique | B6: Protection // Gestion // Sensibilisation. | C6: Surveillance et Police // Suivis, études et inventaires, recherche // Gestion hab-esp, travaux d’entretien et d’équipement // Pédagogie, information, animation, édition // Suivi administratif et financier. | D6: Nombre cité d'animation par rapport à la programmation du site | E6: Nom exact du/des organisme(s) gestionnaire(s) de la RN | F6: Tracé du périmètre | G6: Nombre de règles citées par rapport à la réglementation en place | H6: Espèces représentatives du site citées | I6: Nombre de documents connus par rapport à la documentation en place | J6: Nom(s) cité(s) | K6: Niveau d'accessibilité | L6: Niveau de fréquence | M6: Expression d'un avis | N6: Expression d'un avis | O6: Expression d'un avis | P6: Expression d'un avis | Q6: Expression d'un avis | T6: Expression d'un avis | U6: Echelle de ressenti | V6: Qualification des liens | W6: Taux de fréquence aux animations | X6: Echelle de ressenti | Y6: Echelle de ressenti | Z6: Echelle de ressenti | AA6: Echelle de ressenti | AB6: Echelle de ressenti | AC6: Echelle de ressenti | AD6: Echelle de ressenti | AE6: sans indicateur | AF6: sans indicateur | AG6: sans indicateur
A7: Aide au remplissage des scores | B7: / | C7: / | D7: L'enquêteur écoute la réponse de l'acteur et détermine le gradient de notation | E7: / | F7: / | G7: L'enquêteur écoute la réponse de l'acteur et détermine le gradient de notation | H7: L'enquêteur écoute la réponse de l'acteur et détermine le gradient de notation | I7: L'enquêteur écoute la réponse de l'acteur et détermine le gradient de notation | J7: L'enquêteur écoute et fait le lien entre le nom cité et le poste de la personne | K7: / | L7: / | N7: L'enquêteur écoute la réponse de l'acteur et détermine le gradient de notation | Q7: L'enquêteur écoute la réponse de l'acteur et détermine le gradient de notation | U7: L'enquêteur écoute la réponse de l'acteur et détermine le gradient de notation | V7: / | W7: / | Y7: L'enquêteur écoute la réponse de l'acteur et détermine le gradient de notation | AF7: / | AG7: /
A8: Score 1 | B8: Faux ou non réponse | C8: Faux ou non réponse | D8: Non réponse | E8: Faux ou non réponse | F8: Méconnaissance | G8: Non connue | H8: Faux ou Non connue | I8: Ne connait presque aucun des documents qui lui sont destinés | J8: FAUX ou non réponse | K8: Non | L8: Jamais | M8: Aucun avis | N8: Avis négatif | O8: Pas du tout d'accord | P8: Pas du tout efficace | Q8: Forte critique | R8: Plus-value nulle | S8: Contrainte très forte | T8: Evolution négative des avis | U8: Liens contraints / subis = "RN nous impose un dialogue / une attitude" | V8: Aucun lien | W8: Jamais | X8: Pas du tout | Y8: Tension | Z8: Evolution négative | AA8: Pas du tout | AB8: Non intérêt | AC8: Jamais | AD8: Jamais | AF8: Seulement des inconvénients | AG8: Pas du tout
A9: Score 2 | B9: 1 mission | C9: 1 | D9: x | E9: x | F9: Localisation peu assurée | G9: x | H9: x | J9: x | K9: x | L9: moins d'une fois par an | M9: Avis négatif | N9: Avis critique | O9: Plutôt pas d'accord | P9: Plutôt pas efficace | Q9: Quelques éléments critiquables | R9: Plus-value faible | S9: Plutôt forte | T9: x | U9: x | V9: Liens faibles | W9: <1fois/an | X9: Plutôt non | Y9: Aucun échange / insuffisant | Z9: x | AA9: Plutôt non | AB9: Criticable | AC9: Rarement | AD9: 1x sur les 5 dernières années | AF9: Plus d'inconvénients | AG9: Plutôt non
A10: Score 3 | B10: //si 2 bonnes réponses et 1 réponse fausse// | C10: 2 | D10: moins de 50 % | E10: Incomplet | F10: Localisation globalement correcte | G10: Connaissance floue | H10: Des espèces mais pas celles attendues | I10: Connait la moitié des documents qui lui sont destinés | J10: Structure gestionnaire ou propriétaire | K10: Peu accessible | L10: 1fois/an | M10: Avis mitigé | N10: Avis mitigé ou neutre | O10: Ne peut pas se positionner | P10: Ne peut pas se positionner | Q10: Neutralité | R10: Ne sait pas | S10: Mitigée : contrainte pas complètement acceptée | T10: Pas d'évolution du ressenti | U10: Liens passifs / opportunistes = échanges ou liens lors de visites ou de contrats | V10: Liens moyens | W10: 1fois/an | X10: Mitigé | Y10: Echanges a minima | Z10: Pas d'évolution | AA10: Mitigé | AB10: Pas d'avis | AC10: De temps en temps | AD10: 2x sur les 5 dernières années | AF10: Equilibré ou ne sait pas | AG10: Mitigé
A11: Score 4 | B11: 2 missions claires | C11: 3 | D11: x | E11: x | F11: Bon tracé, quelques approximations peu significatives | G11: x | H11: x | I11: x | J11: x | K11: x | L11: 1fois/trimestre | M11: Avis positif | N11: Avis positif | O11: Plutôt d'accord | P11: Plutôt efficace | Q11: Soutien de principe | R11: Plus-value moyenne | S11: Contrainte acceptée | T11: x | U11: x | V11: Liens forts | W11: 1fois/trimestre | X11: Plutôt oui | Y11: Echanges bienveillants mais peu constructifs | Z11: x | AA11: Plutôt oui | AB11: Correct | AC11: La plupart du temps | AD11: 3x sur les 5 dernières années | AF11: Plus de bénéfices | AG11: Plutôt oui
A12: Score 5 | B12: 3 missions | C12: 4 ou 5 | D12: plus de 50% des animations connues | E12: Exact | F12: Périmètre exact | G12: Principales règlementations connues (qui concernent l'acteur) | H12: Vrai (au moins 1 espèce représentative) | I12: Connait tous les documents qui lui sont destinés | J12: Conservateur.trice ou membre équipe | K12: Facilement accessible | L12: 1fois/mois ou plus | M12: Avis très enthousiaste | N12: Avis très enthousiaste | O12: Tout à fait d'accord | P12: Très efficace | Q12: Fort soutien | R12: Plus-value forte | S12: Pas vécu comme une contrainte | T12: Evolution positive du ressenti | U12: Liens forts, guidés par le partage d'une vocation environnementale (recherché par l'acteur) | V12: Liens d'importance prioritaire | W12: 1fois/mois | X12: Tout à fait | Y12: Echanges bienveillants et constructifs | Z12: Evolution positive | AA12: Tout à fait | AB12: Efficace et légitime | AC12: Toujours | AD12: 4x ou > sur les 5 dernières années | AF12: Seulement des bénéfices | AG12: Tout à fait
A13: Acteur1 (brut) | B13: Entretien d'un site pour favoriser l'habitat des espèces protégées
A14: Acteur1 (score) | B14: 4
A15: Acteur2 (brut) | B15: proteger les petits oiseaux
A16: Acteur2 (score) | B16: 2
A17: Acteur3 (brut)
A18: Acteur3 (score)
A19: Acteur4 (brut)
A20: Acteur4 (score)
A21: Acteur5 (brut)
A22: Acteur5 (score)
A23: Acteur6 (brut)
A24: Acteur6 (score)
A25: Acteur7 (brut)
A26: Acteur7 (score)
A27: Acteur8 (brut)
A28: Acteur8 (score)
... A103: Document mis à disposition sous un contrat Creative Commons CC BY-NC-ND (4.0) https://creativecommons.org/licenses/by-nc-nd/4.0/

Sheet Grille de métriques
C1: CONNAISSANCE | D1: CONNAISSANCE | E1: CONNAISSANCE | F1: CONNAISSANCE | G1: CONNAISSANCE | H1: CONNAISSANCE | I1: CONNAISSANCE | J1: CONNAISSANCE | K1: CONNAISSANCE | L1: CONNAISSANCE | M1: INTERET | N1: INTERET | O1: INTERET | P1: INTERET | Q1: INTERET | R1: INTERET | S1: INTERET | T1: INTERET | U1: INTERET | V1: IMPLICATION | W1: IMPLICATION | X1: IMPLICATION | Y1: IMPLICATION | Z1: IMPLICATION | AA1: IMPLICATION | AB1: métrique complémentaire : CCG | AF1: Conclusion
B2: N° de la métrique | C2: 1 | D2: 2 | E2: 3 | F2: 4 | G2: 5 | H2: 6 | I2: 7 | J2: 8 | K2: 9 | L2: 10 | M2: 11 | N2: 12 | O2: 13 | P2: 14 | Q2: 15 | R2: 16 | S2: 17 | T2: 18 | U2: 19 | V2: 20 | W2: 21 | X2: 22 | Y2: 23 | Z2: 24 | AA2: 25 | AB2: 26 | AC2: 27 | AD2: 28 | AE2: 29 | AF2: 30 | AG2: 31 | AH2: 32
B3: Titre de la métrique | C3: Missions | D3: Actions | E3: Animations | F3: Organisme(s) gestionnaire(s) | G3: Périmètre | H3: Règlementation | I3: Espèce représentative | J3: Outils de communication présentés | K3: Interlocuteurs pour s'informer | L3: Accessibilité à l'infos | M3: Fréquence des visites | N3: Avis sur les animations | O3: Avis sur la Règlementation | P3: Avis sur l'existence | Q3: Avis sur l'efficacité des actions | R3: Avis organisme(s) gestionnaire(s) | S3: Avis sur la plus-value de la réserve | T3: Avis sur les contraintes | U3: Evolution des avis | V3: Nature des liens | W3: Importance des liens | X3: Participation animations | Y3: Impression d'être consulté | Z3: Qualité des échanges | AA3: Evolution des échanges | AB3: Implication CCG | AC3: Avis CCG | AD3: Interventions CCG | AE3: Participation CCG | AF3: Attentes | AG3: Synthèse | AH3: Enracinement
B4: Définition de la métrique | C4: Niveau de connaissance des missions d'une RN en général | D4: Niveau de connaissance des champs d'action de la RN | E4: Niveau de connaissance des animations proposées par la réserve | F4: Niveau de connaissance du gestionnaire de la réserve | G4: Niveau de connaissance réel du périmètre du site | H4: Niveau de connaissance de la règlementation de la RN | I4: Niveau de connaissance des espèces représentatives de la RN | J4: Niveau de connaissance des outils de communication présentés lors de l'entretien | K4: Niveau de connaissance des interlocuteurs de la RN | L4: Niveau d'accessibilité des informations et actualités sur la RN | M4: Fréquentation du site par les acteurs locaux | N4: Evaluation de l'avis sur les animations | O4: Evaluation de l'avis sur la règlementation | P4: Evaluation de l'avis sur l'existence de la réserve | Q4: Evaluation de l'avis sur l'efficacité des actions | R4: Evaluation de l'avis sur l'organisme gestionnaire | S4: Evaluation de la plus-value de la réserve | T4: Evaluation des contraintes induites par la RN | U4: Evaluation de l'évolution des avis à l'égard de la RN | V4: Evaluation de la nature des liens entre acteurs et RN | W4: Evaluation de l'importance des liens | X4: Evaluation de la participation aux animations | Y4: Evaluation du sentiment de consultation sur des sujets qui concernent l'enquêté | Z4: Evaluation du ressenti de la qualité des rapports humains avec l'équipe de la RN. | AA4: Evaluation de l'évolution des échanges avec l'équipe de la réserve | AB4: Evaluation du sentiment d'implication | AC4: Ressenti d'intérêt vis-à-vis de cette instance | AD4: Evaluation de la fréquence d'interventions | AE4: Evaluation de la fréquence de participation
A5: Groupe 1 Membres du CCG | B5: N° | C5: 1 | D5: 2 | E5: 3 | F5: 4 | G5: 5 | H5: 6 | I5: 7 | J5: 8 | K5: 9 | L5: 10 | M5: 11 | N5: 12 | O5: 13 | P5: 14 | Q5: 15 | R5: 16 | S5: 17 | T5: 18 | U5: 19 | V5: 20 | W5: 21 | X5: 22 | Y5: 23 | Z5: 24 | AA5: 25 | AB5: 26 | AC5: 27 | AD5: 28 | AE5: 29 | AF5: 30 | AG5: 31 | AH5: 32
B6: Indicateur | C6: Missions | D6: Actions | E6: Animations | F6: Organisme(s) gestionnaire(s) | G6: Périmètre | H6: Règlementation | I6: Espèce représentative | J6: Outils de communication présentés | K6: Interlocuteurs pour s'informer | L6: Accessibilité à l'infos | M6: Fréquence des visites | N6: Avis sur les animations | O6: Avis sur la Règlementation | P6: Avis sur l'existence | Q6: Avis sur l'efficacité des actions | R6: Avis organisme(s) gestionnaire(s) | S6: Avis sur la plus-value de la réserve | T6: Avis sur les contraintes | U6: Evolution des avis | V6: Importance des liens | W6: Nature des liens | X6: Participation animations | Y6: Impression d'être consulté | Z6: Qualité des échanges | AA6: Evolution des échanges | AB6: Implication CCG | AC6: Avis CCG | AD6: Interventions CCG | AE6: Participation CCG | AF6: Attentes | AG6: Synthèse | AH6: Enracinement
B7: ActeurX
B8: ActeurX
B9: ActeurX
B10: ActeurX
B11: …
B12: MEDIANE Groupe 1 | C12: =MEDIAN(C7:C11) -> #NUM! | D12: =MEDIAN(D7:D11) -> #NUM! | E12: =MEDIAN(E7:E11) -> #NUM! | F12: =MEDIAN(F7:F11) -> #NUM! | G12: =MEDIAN(G7:G11) -> #NUM! | H12: =MEDIAN(H7:H11) -> #NUM! | I12: =MEDIAN(I7:I11) -> #NUM! | J12: =MEDIAN(J7:J11) -> #NUM! | ... AH12: =MEDIAN(AH7:AH11) -> #NUM!
A13: Groupe 2 Partenaires, gestionnaires et techniciens | B13: N° | C13: 1 | D13: 2 | E13: 3 | F13: 4 | G13: 5 | H13: 6 | I13: 7 | J13: 8 | K13: 9 | L13: 10 | M13: 11 | N13: 12 | O13: 13 | P13: 14 | Q13: 15 | R13: 16 | S13: 17 | T13: 18 | U13: 19 | V13: 20 | W13: 21 | X13: 22 | Y13: 23 | Z13: 24 | AA13: 25 | AB13: 26 | AC13: 27 | AD13: 28 | AE13: 29 | AF13: 30 | AG13: 31 | AH13: 32
B14: Indicateur | C14: Missions | D14: Actions | E14: Animations | F14: Organisme(s) gestionnaire(s) | G14: Périmètre | H14: Règlementation | I14: Espèce représentative | J14: Outils de communication présentés | K14: Interlocuteurs pour s'informer | L14: Accessibilité à l'infos | M14: Fréquence des visites | N14: Avis sur les animations | O14: Avis sur la Règlementation | P14: Avis sur l'existence | Q14: Avis sur l'efficacité des actions | R14: Avis organisme(s) gestionnaire(s) | S14: Avis sur la plus-value de la réserve | T14: Avis sur les contraintes | U14: Evolution des avis | V14: Importance des liens | W14: Nature des liens | X14: Participation animations | Y14: Impression d'être consulté | Z14: Qualité des échanges | AA14: Evolution des échanges | AB14: Implication CCG | AC14: Avis CCG | AD14: Interventions CCG | AE14: Participation CCG | AF14: Attentes | AG14: Synthèse | AH14: Enracinement
B15: ActeurX
B16: ActeurX
B17: ActeurX
B18: ActeurX
B19: …
B20: MEDIANE Groupe 2 | C20: =MEDIAN(C15:C19) -> #NUM! | D20: =MEDIAN(D15:D19) -> #NUM! | E20: =MEDIAN(E15:E19) -> #NUM! | F20: =MEDIAN(F15:F19) -> #NUM! | G20: =MEDIAN(G15:G19) -> #NUM! | H20: =MEDIAN(H15:H19) -> #NUM! | I20: =MEDIAN(I15:I19) -> #NUM! | J20: =MEDIAN(J15:J19) -> #NUM! | ... AH20: =MEDIAN(AH15:AH19) -> #NUM!
A21: Groupe 3 Animation, pédagogie, tourisme et sensibilisation | B21: N° | C21: 1 | D21: 2 | E21: 3 | F21: 4 | G21: 5 | H21: 6 | I21: 7 | J21: 8 | K21: 9 | L21: 10 | M21: 11 | N21: 12 | O21: 13 | P21: 14 | Q21: 15 | R21: 16 | S21: 17 | T21: 18 | U21: 19 | V21: 20 | W21: 21 | X21: 22 | Y21: 23 | Z21: 24 | AA21: 25 | AB21: 26 | AC21: 27 | AD21: 28 | AE21: 29 | AF21: 30 | AG21: 31 | AH21: 32
B22: Indicateur | C22: Missions | D22: Actions | E22: Animations | F22: Organisme(s) gestionnaire(s) | G22: Périmètre | H22: Règlementation | I22: Espèce représentative | J22: Outils de communication présentés | K22: Interlocuteurs pour s'informer | L22: Accessibilité à l'infos | M22: Fréquence des visites | N22: Avis sur les animations | O22: Avis sur la Règlementation | P22: Avis sur l'existence | Q22: Avis sur l'efficacité des actions | R22: Avis organisme(s) gestionnaire(s) | S22: Avis sur la plus-value de la réserve | T22: Avis sur les contraintes | U22: Evolution des avis | V22: Importance des liens | W22: Nature des liens | X22: Participation animations | Y22: Impression d'être consulté | Z22: Qualité des échanges | AA22: Evolution des échanges | AB22: Implication CCG | AC22: Avis CCG | AD22: Interventions CCG | AE22: Participation CCG | AF22: Attentes | AG22: Synthèse | AH22: Enracinement
B23: ActeurX
B24: ActeurX
B25: ActeurX
B26: ActeurX
B27: …
B28: MEDIANE Groupe 3 | C28: =MEDIAN(C23:C27) -> #NUM! | D28: =MEDIAN(D23:D27) -> #NUM! | E28: =MEDIAN(E23:E27) -> #NUM! | F28: =MEDIAN(F23:F27) -> #NUM! | G28: =MEDIAN(G23:G27) -> #NUM! | H28: =MEDIAN(H23:H27) -> #NUM! | I28: =MEDIAN(I23:I27) -> #NUM! | J28: =MEDIAN(J23:J27) -> #NUM! | ... AH28: =MEDIAN(AH23:AH27) -> #NUM!
A29: Groupe 4 Riverains, élus et usagers locaux | B29: N° | C29: 1 | D29: 2 | E29: 3 | F29: 4 | G29: 5 | H29: 6 | I29: 7 | J29: 8 | K29: 9 | L29: 10 | M29: 11 | N29: 12 | O29: 13 | P29: 14 | Q29: 15 | R29: 16 | S29: 17 | T29: 18 | U29: 19 | V29: 20 | W29: 21 | X29: 22 | Y29: 23 | Z29: 24 | AA29: 25 | AB29: 26 | AC29: 27 | AD29: 28 | AE29: 29 | AF29: 30 | AG29: 31 | AH29: 32
B30: Indicateur | C30: Missions | D30: Actions | E30: Animations | F30: Organisme(s) gestionnaire(s) | G30: Périmètre | H30: Règlementation | I30: Espèce représentative | J30: Outils de communication présentés | K30: Interlocuteurs pour s'informer | L30: Accessibilité à l'infos | M30: Fréquence des visites | N30: Avis sur les animations | O30: Avis sur la Règlementation | P30: Avis sur l'existence | Q30: Avis sur l'efficacité des actions | R30: Avis organisme(s) gestionnaire(s) | S30: Avis sur la plus-value de la réserve | T30: Avis sur les contraintes | U30: Evolution des avis | V30: Importance des liens | W30: Nature des liens | X30: Participation animations | Y30: Impression d'être consulté | Z30: Qualité des échanges | AA30: Evolution des échanges | AB30: Implication CCG | AC30: Avis CCG | AD30: Interventions CCG | AE30: Participation CCG | AF30: Attentes | AG30: Synthèse | AH30: Enracinement
B31: ActeurX
B32: ActeurX
B33: ActeurX
B34: ActeurX
B35: …
B36: MEDIANE Groupe 4 | C36: =MEDIAN(C31:C35) -> #NUM! | D36: =MEDIAN(D31:D35) -> #NUM! | E36: =MEDIAN(E31:E35) -> #NUM! | F36: =MEDIAN(F31:F35) -> #NUM! | G36: =MEDIAN(G31:G35) -> #NUM! | H36: =MEDIAN(H31:H35) -> #NUM! | I36: =MEDIAN(I31:I35) -> #NUM! | J36: =MEDIAN(J31:J35) -> #NUM! | ... AH36: =MEDIAN(AH31:AH35) -> #NUM!
A37: Groupe 5 Acteurs économiques | B37: N° | C37: 1 | D37: 2 | E37: 3 | F37: 4 | G37: 5 | H37: 6 | I37: 7 | J37: 8 | K37: 9 | L37: 10 | M37: 11 | N37: 12 | O37: 13 | P37: 14 | Q37: 15 | R37: 16 | S37: 17 | T37: 18 | U37: 19 | V37: 20 | W37: 21 | X37: 22 | Y37: 23 | Z37: 24 | AA37: 25 | AB37: 26 | AC37: 27 | AD37: 28 | AE37: 29 | AF37: 30 | AG37: 31 | AH37: 32
B38: Indicateur | C38: Missions | D38: Actions | E38: Animations | F38: Organisme(s) gestionnaire(s) | G38: Périmètre | H38: Règlementation | I38: Espèce représentative | J38: Outils de communication présentés | K38: Interlocuteurs pour s'informer | L38: Accessibilité à l'infos | M38: Fréquence des visites | N38: Avis sur les animations | O38: Avis sur la Règlementation | P38: Avis sur l'existence | Q38: Avis sur l'efficacité des actions | R38: Avis organisme(s) gestionnaire(s) | S38: Avis sur la plus-value de la réserve | T38: Avis sur les contraintes | U38: Evolution des avis | V38: Importance des liens | W38: Nature des liens | X38: Participation animations | Y38: Impression d'être consulté | Z38: Qualité des échanges | AA38: Evolution des échanges | AB38: Implication CCG | AC38: Avis CCG | AD38: Interventions CCG | AE38: Participation CCG | AF38: Attentes | AG38: Synthèse | AH38: Enracinement
B39: ActeurX
B40: ActeurX
...

Sheet Graphs Connaissance
C1: CONNAISSANCE | D1: CONNAISSANCE | E1: CONNAISSANCE | F1: CONNAISSANCE | G1: CONNAISSANCE | H1: CONNAISSANCE | I1: CONNAISSANCE | J1: CONNAISSANCE | K1: CONNAISSANCE | L1: CONNAISSANCE
B2: N° de la métrique | C2: 1 | D2: 2 | E2: 3 | F2: 4 | G2: 5 | H2: 6 | I2: 7 | J2: 8 | K2: 9 | L2: 10
B3: Titre de la métrique | C3: Missions | D3: Actions | E3: Animations | F3: Organisme(s) gestionnaire(s) | G3: Périmètre | H3: Règlementation | I3: Espèce représentative | J3: Outils de communication présentés | K3: Interlocuteurs pour s'informer | L3: Accessibilité à l'infos
B4: Définition de la métrique | C4: Niveau de connaissance des missions d'une RN en général | D4: Niveau de connaissance des champs d'action de la RN | E4: Niveau de connaissance des animations proposées par la réserve | F4: Niveau de connaissance du gestionnaire de la réserve | G4: Niveau de connaissance réel du périmètre du site | H4: Niveau de connaissance de la règlementation de la RN | I4: Niveau de connaissance des espèces représentatives de la RN | J4: Niveau de connaissance des outils de communication présentés lors de l'entretien | K4: Niveau de connaissance des interlocuteurs de la RN | L4: Niveau d'accessibilité des informations et actualités sur la RN
B5: Question liée à la métrique dans la trame d'entretien | C5: Selon-vous, quelles sont les missions d'une réserve naturelle, en général ? | D5: Concrètement, savez-vous ce qui se fait sur cette réserve ? | E5: Connaissez-vous des animations proposées par la réserve et lesquelles ? | F5: Connaissez vous les organismes gestionnaires de la réserve ? | G5: Voulez-vous bien tracer le périmètre de la réserve sur une carte ? | H5: Connaissez-vous des règles à respecter sur la réserve ? | I5: Selon vous, quelles sont les especes représentatives de la réserve ? | J5: Parmi les documents suivants, lesquels connaissez-vous ? | K5: Vers qui vous tournez vous pour avoir des informations ? | L5: Les informations sur la RN sont elles accessibles ?
B6: Réponse attendue à la métrique | C6: Protection // Gestion // Sensibilisation. | D6: Surveillance et Police // Suivis, études et inventaires, recherche // Gestion hab-esp, travaux d’entretien et d’équipement // Pédagogie, information, animation, édition // Suivi administratif et financier. | E6: Nombre cité d'animation par rapport à la programmation du site | F6: Nom exact du/des organisme(s) gestionnaire(s) de la RN | G6: Tracé du périmètre | H6: Nombre de règles citées par rapport à la réglementation en place | I6: Espèces représentatives du site citées | J6: Nombre de documents connus par rapport à la documentation en place | K6: Nom(s) cité(s) | L6: Niveau d'accessibilité
B7: Score 1 | C7: Faux ou non réponse | D7: Faux ou non réponse | E7: Non réponse | F7: Faux ou non réponse | G7: Méconnaissance | H7: Non connue | I7: Faux ou Non connue | J7: Ne connait presque aucun des documents qui lui sont destinés | K7: FAUX ou non réponse | L7: Non
B8: Score 2 | C8: 1 mission | D8: 1 | E8: x | F8: x | G8: Localisation peu assurée | H8: x | I8: x | J8: x | K8: x | L8: x
B9: Score 3 | C9: //si 2 bonnes réponses et 1 réponse fausse// | D9: 2 | E9: moins de 50 % | F9: Incomplet | G9: Localisation globalement correcte | H9: Connaissance floue | I9: Des espèces mais pas celles attendues | J9: Connait la moitié des documents qui lui sont destinés | K9: Structure gestionnaire ou propriétaire | L9: Peu accessible
B10: Score 4 | C10: 2 missions claires | D10: 3 | E10: x | F10: x | G10: Bon tracé, quelques approximations peu significatives | H10: x | I10: x | J10: x | K10: x | L10: x
B11: Score 5 | C11: 3 missions | D11: 4 ou 5 | E11: plus de 50% des animations connues | F11: Exact | G11: Périmètre exact | H11: Principales règlementations connues (qui concernent l'acteur) | I11: Vrai (au moins 1 espèce emblematique) | J11: Connait tous les documents qui lui sont destinés | K11: Conservateur.trice ou membre équipe | L11: Facilement accessible
C12: Finalité | D12: Actions | E12: Animations | F12: Gestionnaire | G12: Périmètre | H12: Règlementation | I12: Espèces | J12: Communication | K12: Contact | L12: Informations
B13: MEDIANE Groupe 1 | C13: ='Grille de métriques'!C12 -> #NUM! | D13: ='Grille de métriques'!D12 -> #NUM! | E13: ='Grille de métriques'!E12 -> #NUM! | F13: ='Grille de métriques'!F12 -> #NUM! | G13: ='Grille de métriques'!G12 -> #NUM! | H13: ='Grille de métriques'!H12 -> #NUM! | I13: ='Grille de métriques'!I12 -> #NUM! | J13: ='Grille de métriques'!J12 -> #NUM! | ... L13: ='Grille de métriques'!L12 -> #NUM!
B14: MEDIANE Groupe 2 | C14: ='Grille de métriques'!C20 -> #NUM! | D14: ='Grille de métriques'!D20 -> #NUM! | E14: ='Grille de métriques'!E20 -> #NUM! | F14: ='Grille de métriques'!F20 -> #NUM! | G14: ='Grille de métriques'!G20 -> #NUM! | H14: ='Grille de métriques'!H20 -> #NUM! | I14: ='Grille de métriques'!I20 -> #NUM! | J14: ='Grille de métriques'!J20 -> #NUM! | ... L14: ='Grille de métriques'!L20 -> #NUM!
B15: MEDIANE Groupe 3 | C15: ='Grille de métriques'!C28 -> #NUM! | D15: ='Grille de métriques'!D28 -> #NUM! | E15: ='Grille de métriques'!E28 -> #NUM! | F15: ='Grille de métriques'!F28 -> #NUM! | G15: ='Grille de métriques'!G28 -> #NUM! | H15: ='Grille de métriques'!H28 -> #NUM! | I15: ='Grille de métriques'!I28 -> #NUM! | J15: ='Grille de métriques'!J28 -> #NUM! | ... L15: ='Grille de métriques'!L28 -> #NUM!
B16: MEDIANE Groupe 4 | C16: ='Grille de métriques'!C36 -> #NUM! | D16: ='Grille de métriques'!D36 -> #NUM! | E16: ='Grille de métriques'!E36 -> #NUM! | F16: ='Grille de métriques'!F36 -> #NUM! | G16: ='Grille de métriques'!G36 -> #NUM! | H16: ='Grille de métriques'!H36 -> #NUM! | I16: ='Grille de métriques'!I36 -> #NUM! | J16: ='Grille de métriques'!J36 -> #NUM! | ... L16: ='Grille de métriques'!L36 -> #NUM!
B17: MEDIANE Groupe 5 | C17: ='Grille de métriques'!C44 -> #NUM! | D17: ='Grille de métriques'!D44 -> #NUM! | E17: ='Grille de métriques'!E44 -> #NUM! | F17: ='Grille de métriques'!F44 -> #NUM! | G17: ='Grille de métriques'!G44 -> #NUM! | H17: ='Grille de métriques'!H44 -> #NUM! | I17: ='Grille de métriques'!I44 -> #NUM! | J17: ='Grille de métriques'!J44 -> #NUM! | ... L17: ='Grille de métriques'!L44 -> #NUM!
B18: MEDIANE Tous acteurs | C18: ='Grille de métriques'!C87 -> 0 | D18: ='Grille de métriques'!D87 -> 0 | E18: ='Grille de métriques'!E87 -> 0 | F18: ='Grille de métriques'!F87 -> 0 | G18: ='Grille de métriques'!G87 -> 0 | H18: ='Grille de métriques'!H87 -> 0 | I18: ='Grille de métriques'!I87 -> 0 | J18: ='Grille de métriques'!J87 -> 0 | ... L18: ='Grille de métriques'!L87 -> 0
C19: Finalité | D19: Actions | E19: Animations | F19: Gestionnaire | G19: Périmètre | H19: Règlementation | I19: Espèces | J19: Communication | K19: Contact | L19: Informations
B20: Acteur1 | C20: =Formulaire!B13 -> Entretien d'un site pour favoriser l'habitat des espèces protégées | D20: =Formulaire!C13 -> 0 | E20: =Formulaire!D13 -> 0 | F20: =Formulaire!E13 -> 0 | G20: =Formulaire!F13 -> 0 | H20: =Formulaire!G13 -> 0 | I20: =Formulaire!H13 -> 0 | J20: =Formulaire!I13 -> 0 | ... L20: =Formulaire!K13 -> 0
B21: Acteur2 | C21: =Formulaire!B15 -> proteger les petits oiseaux | D21: =Formulaire!C15 -> 0 | E21: =Formulaire!D15 -> 0 | F21: =Formulaire!E15 -> 0 | G21: =Formulaire!F15 -> 0 | H21: =Formulaire!G15 -> 0 | I21: =Formulaire!H15 -> 0 | J21: =Formulaire!I15 -> 0 | ... L21: =Formulaire!K15 -> 0
B22: Acteur3 | C22: =Formulaire!B17 -> 0 | D22: =Formulaire!C17 -> 0 | E22: =Formulaire!D17 -> 0 | F22: =Formulaire!E17 -> 0 | G22: =Formulaire!F17 -> 0 | H22: =Formulaire!G17 -> 0 | I22: =Formulaire!H17 -> 0 | J22: =Formulaire!I17 -> 0 | ... L22: =Formulaire!K17 -> 0
B23: Acteur4 | C23: =Formulaire!B19 -> 0 | D23: =Formulaire!C19 -> 0 | E23: =Formulaire!D19 -> 0 | F23: =Formulaire!E19 -> 0 | G23: =Formulaire!F19 -> 0 | H23: =Formulaire!G19 -> 0 | I23: =Formulaire!H19 -> 0 | J23: =Formulaire!I19 -> 0 | ... L23: =Formulaire!K19 -> 0
B24: Acteur5 | C24: =Formulaire!B21 -> 0 | D24: =Formulaire!C21 -> 0 | E24: =Formulaire!D21 -> 0 | F24: =Formulaire!E21 -> 0 | G24: =Formulaire!F21 -> 0 | H24: =Formulaire!G21 -> 0 | I24: =Formulaire!H21 -> 0 | J24: =Formulaire!I21 -> 0 | ... L24: =Formulaire!K21 -> 0
B25: Acteur6 | C25: =Formulaire!B23 -> 0 | D25: =Formulaire!C23 -> 0 | E25: =Formulaire!D23 -> 0 | F25: =Formulaire!E23 -> 0 | G25: =Formulaire!F23 -> 0 | H25: =Formulaire!G23 -> 0 | I25: =Formulaire!H23 -> 0 | J25: =Formulaire!I23 -> 0 | ... L25: =Formulaire!K23 -> 0
B26: Acteur7 | C26: =Formulaire!B25 -> 0 | D26: =Formulaire!C25 -> 0 | E26: =Formulaire!D25 -> 0 | F26: =Formulaire!E25 -> 0 | G26: =Formulaire!F25 -> 0 | H26: =Formulaire!G25 -> 0 | I26: =Formulaire!H25 -> 0 | J26: =Formulaire!I25 -> 0 | ... L26: =Formulaire!K25 -> 0
B27: Acteur8 | C27: =Formulaire!B27 -> 0 | D27: =Formulaire!C27 -> 0 | E27: =Formulaire!D27 -> 0 | F27: =Formulaire!E27 -> 0 | G27: =Formulaire!F27 -> 0 | H27: =Formulaire!G27 -> 0 | I27: =Formulaire!H27 -> 0 | J27: =Formulaire!I27 -> 0 | ... L27: =Formulaire!K27 -> 0
B28: Acteur9 | C28: =Formulaire!B29 -> 0 | D28: =Formulaire!C29 -> 0 | E28: =Formulaire!D29 -> 0 | F28: =Formulaire!E29 -> 0 | G28: =Formulaire!F29 -> 0 | H28: =Formulaire!G29 -> 0 | I28: =Formulaire!H29 -> 0 | J28: =Formulaire!I29 -> 0 | ... L28: =Formulaire!K29 -> 0
B29: Acteur10 | C29: =Formulaire!B31 -> 0 | D29: =Formulaire!C31 -> 0 | E29: =Formulaire!D31 -> 0 | F29: =Formulaire!E31 -> 0 | G29: =Formulaire!F31 -> 0 | H29: =Formulaire!G31 -> 0 | I29: =Formulaire!H31 -> 0 | J29: =Formulaire!I31 -> 0 | ... L29: =Formulaire!K31 -> 0
B30: Acteur11 | C30: =Formulaire!B33 -> 0 | D30: =Formulaire!C33 -> 0 | E30: =Formulaire!D33 -> 0 | F30: =Formulaire!E33 -> 0 | G30: =Formulaire!F33 -> 0 | H30: =Formulaire!G33 -> 0 | I30: =Formulaire!H33 -> 0 | J30: =Formulaire!I33 -> 0 | ... L30: =Formulaire!K33 -> 0
B31: Acteur12 | C31: =Formulaire!B35 -> 0 | D31: =Formulaire!C35 -> 0 | E31: =Formulaire!D35 -> 0 | F31: =Formulaire!E35 -> 0 | G31: =Formulaire!F35 -> 0 | H31: =Formulaire!G35 -> 0 | I31: =Formulaire!H35 -> 0 | J31: =Formulaire!I35 -> 0 | ... L31: =Formulaire!K35 -> 0
B32: Acteur13 | C32: =Formulaire!B37 -> 0 | D32: =Formulaire!C37 -> 0 | E32: =Formulaire!D37 -> 0 | F32: =Formulaire!E37 -> 0 | G32: =Formulaire!F37 -> 0 | H32: =Formulaire!G37 -> 0 | I32: =Formulaire!H37 -> 0 | J32: =Formulaire!I37 -> 0 | ... L32: =Formulaire!K37 -> 0
B33: Acteur14 | C33: =Formulaire!B39 -> 0 | D33: =Formulaire!C39 -> 0 | E33: =Formulaire!D39 -> 0 | F33: =Formulaire!E39 -> 0 | G33: =Formulaire!F39 -> 0 | H33: =Formulaire!G39 -> 0 | I33: =Formulaire!H39 -> 0 | J33: =Formulaire!I39 -> 0 | ... L33: =Formulaire!K39 -> 0
B34: Acteur15 | C34: =Formulaire!B41 -> 0 | D34: =Formulaire!C41 -> 0 | E34: =Formulaire!D41 -> 0 | F34: =Formulaire!E41 -> 0 | G34: =Formulaire!F41 -> 0 | H34: =Formulaire!G41 -> 0 | I34: =Formulaire!H41 -> 0 | J34: =Formulaire!I41 -> 0 | ... L34: =Formulaire!K41 -> 0
B35: Acteur16 | C35: =Formulaire!B43 -> 0 | D35: =Formulaire!C43 -> 0 | E35: =Formulaire!D43 -> 0 | F35: =Formulaire!E43 -> 0 | G35: =Formulaire!F43 -> 0 | H35: =Formulaire!G43 -> 0 | I35: =Formulaire!H43 -> 0 | J35: =Formulaire!I43 -> 0 | ... L35: =Formulaire!K43 -> 0
B36: Acteur17 | C36: =Formulaire!B45 -> 0 | D36: =Formulaire!C45 -> 0 | E36: =Formulaire!D45 -> 0 | F36: =Formulaire!E45 -> 0 | G36: =Formulaire!F45 -> 0 | H36: =Formulaire!G45 -> 0 | I36: =Formulaire!H45 -> 0 | J36: =Formulaire!I45 -> 0 | ... L36: =Formulaire!K45 -> 0
B37: Acteur18 | C37: =Formulaire!B47 -> 0 | D37: =Formulaire!C47 -> 0 | E37: =Formulaire!D47 -> 0 | F37: =Formulaire!E47 -> 0 | G37: =Formulaire!F47 -> 0 | H37: =Formulaire!G47 -> 0 | I37: =Formulaire!H47 -> 0 | J37: =Formulaire!I47 -> 0 | ... L37: =Formulaire!K47 -> 0
B38: Acteur19 | C38: =Formulaire!B49 -> 0 | D38: =Formulaire!C49 -> 0 | E38: =Formulaire!D49 -> 0 | F38: =Formulaire!E49 -> 0 | G38: =Formulaire!F49 -> 0 | H38: =Formulaire!G49 -> 0 | I38: =Formulaire!H49 -> 0 | J38: =Formulaire!I49 -> 0 | ... L38: =Formulaire!K49 -> 0
B39: Acteur20 | C39: =Formulaire!B51 -> 0 | D39: =Formulaire!C51 -> 0 | E39: =Formulaire!D51 -> 0 | F39: =Formulaire!E51 -> 0 | G39: =Formulaire!F51 -> 0 | H39: =Formulaire!G51 -> 0 | I39: =Formulaire!H51 -> 0 | J39: =Formulaire!I51 -> 0 | ... L39: =Formulaire!K51 -> 0
B40: Acteur21 | C40: =Formulaire!B53 -> 0 | D40: =Formulaire!C53 -> 0 | E40: =Formulaire!D53 -> 0 | F40: =Formulaire!E53 -> 0 | G40: =Formulaire!F53 -> 0 | H40: =Formulaire!G53 -> 0 | I40: =Formulaire!H53 -> 0 | J40: =Formulaire!I53 -> 0 | ... L40: =Formulaire!K53 -> 0
...

Sheet Graphs Interet
C1: INTERET | D1: INTERET | E1: INTERET | F1: INTERET | G1: INTERET | H1: INTERET | I1: INTERET | J1: INTERET | K1: INTERET
B2: N° | C2: 11 | D2: 12 | E2: 13 | F2: 14 | G2: 15 | H2: 16 | I2: 17 | J2: 18 | K2: 19
B3: Indicateur | C3: Fréquence des visites | D3: Avis sur les animations | E3: Avis sur la Règlementation | F3: Avis sur l'existence | G3: Avis sur l'efficacité des actions | H3: Avis organisme(s) gestionnaire(s) | I3: Avis sur la plus-value de la réserve | J3: Avis sur les contraintes | K3: Evolution des avis
B4: Définition de la métrique | C4: Fréquentation du site par les acteurs locaux | D4: Evaluation de l'avis sur les animations | E4: Evaluation de l'avis sur la règlementation | F4: Evaluation de l'avis sur l'existence de la réserve | G4: Evaluation de l'avis sur l'efficacité des actions | H4: Evaluation de l'avis sur l'organisme gestionnaire | I4: Evaluation de la plus-value de la réserve | J4: Evaluation des contraintes induites par la RN | K4: Evaluation de l'évolution des avis à l'égard de la RN
B5: Question | C5: A quelle fréquence venez-vous voir la réserve pour des raisons professionnelles ou de loisirs ? | D5: Quel est votre avis sur les animations ? | E5: Quel est votre avis sur la réglementation ? | F5: Est-ce que vous êtes d’accord avec l’existence de la réserve ici ? | G5: Pensez-vous que ces actions soient globalement efficaces ? | H5: Quel est votre avis sur l’organisme gestionnaire ? | I5: La réserve représente-elle une/des plus-values pour vous ? | J5: La réserve représente-t-elle des contraintes pour vous ? | K5: Avec le temps et globalement, est-ce que votre avis sur la réserve a évolué ?
B6: Réponse attendue | C6: Niveau de fréquence | D6: Expression d'un avis | E6: Expression d'un avis | F6: Expression d'un avis | G6: Expression d'un avis | H6: Expression d'un avis | K6: Expression d'un avis
B7: Score 1 | C7: Jamais | D7: Avis négatif | E7: Aucun avis | F7: Pas du tout d'accord | G7: Pas du tout efficace | H7: Forte critique | I7: Plus-value nulle | J7: Contrainte très forte | K7: Evolution négative des avis
B8: Score 2 | C8: moins d'une fois par an | D8: Avis négatif | E8: Avis critique | F8: Plutôt pas d'accord | G8: Plutôt pas efficace | H8: Quelques éléments critiquables | I8: Plus-value faible | J8: Plutôt forte | K8: x
B9: Score 3 | C9: 1fois/an | D9: Avis mitigé | E9: Avis mitigé ou neutre | F9: Ne peut pas se positionner | G9: Ne peut pas se positionner | H9: Neutralité | I9: Ne sait pas | J9: Mitigée : contrainte pas complètement acceptée | K9: Pas d'évolution du ressenti
B10: Score 4 | C10: 1fois/trimestre | D10: Avis positif | E10: Avis positif | F10: Plutôt d'accord | G10: Plutôt efficace | H10: Soutien de principe | I10: Plus-value moyenne | J10: Contrainte acceptée | K10: x
B11: Score 5 | C11: 1fois/mois ou plus | D11: Avis très enthousiaste | E11: Avis très enthousiaste | F11: Tout à fait d'accord | G11: Très efficace | H11: Fort soutien | I11: Plus-value forte | J11: Pas vécu comme une contrainte | K11: Evolution positive du ressenti
C12: Fréquence visites | D12: Animations avis | E12: Règlementation acceptée | F12: Importance | G12: Efficacité | H12: Gestion | I12: Gestionnaire | J12: Plus values territoire | K12: Plus values perso
B13: MEDIANE Groupe 1 | C13: ='Grille de métriques'!M12 -> #NUM! | D13: ='Grille de métriques'!N12 -> #NUM! | E13: ='Grille de métriques'!O12 -> #NUM! | F13: ='Grille de métriques'!P12 -> #NUM! | G13: ='Grille de métriques'!Q12 -> #NUM! | H13: ='Grille de métriques'!R12 -> #NUM! | I13: ='Grille de métriques'!S12 -> #NUM! | J13: ='Grille de métriques'!T12 -> #NUM! | K13: ='Grille de métriques'!U12 -> #NUM!
B14: MEDIANE Groupe 2 | C14: ='Grille de métriques'!M20 -> #NUM! | D14: ='Grille de métriques'!N20 -> #NUM! | E14: ='Grille de métriques'!O20 -> #NUM! | F14: ='Grille de métriques'!P20 -> #NUM! | G14: ='Grille de métriques'!Q20 -> #NUM! | H14: ='Grille de métriques'!R20 -> #NUM! | I14: ='Grille de métriques'!S20 -> #NUM! | J14: ='Grille de métriques'!T20 -> #NUM! | K14: ='Grille de métriques'!U20 -> #NUM!
B15: MEDIANE Groupe 3 | C15: ='Grille de métriques'!M28 -> #NUM! | D15: ='Grille de métriques'!N28 -> #NUM! | E15: ='Grille de métriques'!O28 -> #NUM! | F15: ='Grille de métriques'!P28 -> #NUM! | G15: ='Grille de métriques'!Q28 -> #NUM! | H15: ='Grille de métriques'!R28 -> #NUM! | I15: ='Grille de métriques'!S28 -> #NUM! | J15: ='Grille de métriques'!T28 -> #NUM! | K15: ='Grille de métriques'!U28 -> #NUM!
B16: MEDIANE Groupe 4 | C16: ='Grille de métriques'!M36 -> #NUM! | D16: ='Grille de métriques'!N36 -> #NUM! | E16: ='Grille de métriques'!O36 -> #NUM! | F16: ='Grille de métriques'!P36 -> #NUM! | G16: ='Grille de métriques'!Q36 -> #NUM! | H16: ='Grille de métriques'!R36 -> #NUM! | I16: ='Grille de métriques'!S36 -> #NUM! | J16: ='Grille de métriques'!T36 -> #NUM! | K16: ='Grille de métriques'!U36 -> #NUM!
B17: MEDIANE Groupe 5 | C17: ='Grille de métriques'!M44 -> #NUM! | D17: ='Grille de métriques'!N44 -> #NUM! | E17: ='Grille de métriques'!O44 -> #NUM! | F17: ='Grille de métriques'!P44 -> #NUM! | G17: ='Grille de métriques'!Q44 -> #NUM! | H17: ='Grille de métriques'!R44 -> #NUM! | I17: ='Grille de métriques'!S44 -> #NUM! | J17: ='Grille de métriques'!T44 -> #NUM! | K17: ='Grille de métriques'!U44 -> #NUM!
B18: MEDIANE Tous acteurs | C18: ='Grille de métriques'!M87 -> 0 | D18: ='Grille de métriques'!N87 -> 0 | E18: ='Grille de métriques'!O87 -> 0 | F18: ='Grille de métriques'!P87 -> 0 | G18: ='Grille de métriques'!Q87 -> 0 | H18: ='Grille de métriques'!R87 -> 0 | I18: ='Grille de métriques'!S87 -> 0 | J18: ='Grille de métriques'!T87 -> 0 | K18: ='Grille de métriques'!U87 -> 0
C19: Fréquence visites | D19: Animations avis | E19: Règlementation acceptée | F19: Importance | G19: Efficacité | H19: Gestion | I19: Gestionnaire | J19: Plus values territoire | K19: Plus values perso
B20: Acteur1 | C20: =Formulaire!L13 -> 0 | D20: =Formulaire!M13 -> 0 | E20: =Formulaire!N13 -> 0 | F20: =Formulaire!O13 -> 0 | G20: =Formulaire!P13 -> 0 | H20: =Formulaire!Q13 -> 0 | I20: =Formulaire!R13 -> 0 | J20: =Formulaire!S13 -> 0 | K20: =Formulaire!T13 -> 0
B21: Acteur2 | C21: =Formulaire!L15 -> 0 | D21: =Formulaire!M15 -> 0 | E21: =Formulaire!N15 -> 0 | F21: =Formulaire!O15 -> 0 | G21: =Formulaire!P15 -> 0 | H21: =Formulaire!Q15 -> 0 | I21: =Formulaire!R15 -> 0 | J21: =Formulaire!S15 -> 0 | K21: =Formulaire!T15 -> 0
B22: Acteur3 | C22: =Formulaire!L17 -> 0 | D22: =Formulaire!M17 -> 0 | E22: =Formulaire!N17 -> 0 | F22: =Formulaire!O17 -> 0 | G22: =Formulaire!P17 -> 0 | H22: =Formulaire!Q17 -> 0 | I22: =Formulaire!R17 -> 0 | J22: =Formulaire!S17 -> 0 | K22: =Formulaire!T17 -> 0
B23: Acteur4 | C23: =Formulaire!L19 -> 0 | D23: =Formulaire!M19 -> 0 | E23: =Formulaire!N19 -> 0 | F23: =Formulaire!O19 -> 0 | G23: =Formulaire!P19 -> 0 | H23: =Formulaire!Q19 -> 0 | I23: =Formulaire!R19 -> 0 | J23: =Formulaire!S19 -> 0 | K23: =Formulaire!T19 -> 0
B24: Acteur5 | C24: =Formulaire!L21 -> 0 | D24: =Formulaire!M21 -> 0 | E24: =Formulaire!N21 -> 0 | F24: =Formulaire!O21 -> 0 | G24: =Formulaire!P21 -> 0 | H24: =Formulaire!Q21 | I24: =Formulaire!R21 -> 0 | J24: =Formulaire!S21 -> 0 | K24: =Formulaire!T21 -> 0
B25: Acteur6 | C25: =Formulaire!L23 -> 0 | D25: =Formulaire!M23 -> 0 | E25: =Formulaire!N23 -> 0 | F25: =Formulaire!O23 -> 0 | G25: =Formulaire!P23 -> 0 | H25: =Formulaire!Q23 -> 0 | I25: =Formulaire!R23 -> 0 | J25: =Formulaire!S23 -> 0 | K25: =Formulaire!T23 -> 0
B26: Acteur7 | C26: =Formulaire!L25 -> 0 | D26: =Formulaire!M25 -> 0 | E26: =Formulaire!N25 -> 0 | F26: =Formulaire!O25 -> 0 | G26: =Formulaire!P25 -> 0 | H26: =Formulaire!Q25 -> 0 | I26: =Formulaire!R25 -> 0 | J26: =Formulaire!S25 -> 0 | K26: =Formulaire!T25 -> 0
B27: Acteur8 | C27: =Formulaire!L27 -> 0 | D27: =Formulaire!M27 -> 0 | E27: =Formulaire!N27 -> 0 | F27: =Formulaire!O27 -> 0 | G27: =Formulaire!P27 -> 0 | H27: =Formulaire!Q27 -> 0 | I27: =Formulaire!R27 -> 0 | J27: =Formulaire!S27 -> 0 | K27: =Formulaire!T27 -> 0
B28: Acteur9 | C28: =Formulaire!L29 -> 0 | D28: =Formulaire!M29 -> 0 | E28: =Formulaire!N29 -> 0 | F28: =Formulaire!O29 -> 0 | G28: =Formulaire!P29 -> 0 | H28: =Formulaire!Q29 -> 0 | I28: =Formulaire!R29 -> 0 | J28: =Formulaire!S29 -> 0 | K28: =Formulaire!T29 -> 0
B29: Acteur10 | C29: =Formulaire!L31 -> 0 | D29: =Formulaire!M31 -> 0 | E29: =Formulaire!N31 -> 0 | F29: =Formulaire!O31 -> 0 | G29: =Formulaire!P31 -> 0 | H29: =Formulaire!Q31 -> 0 | I29: =Formulaire!R31 -> 0 | J29: =Formulaire!S31 -> 0 | K29: =Formulaire!T31 -> 0
B30: Acteur11 | C30: =Formulaire!L33 -> 0 | D30: =Formulaire!M33 -> 0 | E30: =Formulaire!N33 -> 0 | F30: =Formulaire!O33 -> 0 | G30: =Formulaire!P33 -> 0 | H30: =Formulaire!Q33 -> 0 | I30: =Formulaire!R33 -> 0 | J30: =Formulaire!S33 -> 0 | K30: =Formulaire!T33 -> 0
B31: Acteur12 | C31: =Formulaire!L35 -> 0 | D31: =Formulaire!M35 -> 0 | E31: =Formulaire!N35 -> 0 | F31: =Formulaire!O35 -> 0 | G31: =Formulaire!P35 -> 0 | H31: =Formulaire!Q35 -> 0 | I31: =Formulaire!R35 -> 0 | J31: =Formulaire!S35 -> 0 | K31: =Formulaire!T35 -> 0
B32: Acteur13 | C32: =Formulaire!L37 -> 0 | D32: =Formulaire!M37 -> 0 | E32: =Formulaire!N37 -> 0 | F32: =Formulaire!O37 -> 0 | G32: =Formulaire!P37 -> 0 | H32: =Formulaire!Q37 -> 0 | I32: =Formulaire!R37 -> 0 | J32: =Formulaire!S37 -> 0 | K32: =Formulaire!T37 -> 0
B33: Acteur14 | C33: =Formulaire!L39 -> 0 | D33: =Formulaire!M39 -> 0 | E33: =Formulaire!N39 -> 0 | F33: =Formulaire!O39 -> 0 | G33: =Formulaire!P39 -> 0 | H33: =Formulaire!Q39 -> 0 | I33: =Formulaire!R39 -> 0 | J33: =Formulaire!S39 -> 0 | K33: =Formulaire!T39 -> 0
B34: Acteur15 | C34: =Formulaire!L41 -> 0 | D34: =Formulaire!M41 -> 0 | E34: =Formulaire!N41 -> 0 | F34: =Formulaire!O41 -> 0 | G34: =Formulaire!P41 -> 0 | H34: =Formulaire!Q41 -> 0 | I34: =Formulaire!R41 -> 0 | J34: =Formulaire!S41 -> 0 | K34: =Formulaire!T41 -> 0
B35: Acteur16 | C35: =Formulaire!L43 -> 0 | D35: =Formulaire!M43 -> 0 | E35: =Formulaire!N43 -> 0 | F35: =Formulaire!O43 -> 0 | G35: =Formulaire!P43 -> 0 | H35: =Formulaire!Q43 -> 0 | I35: =Formulaire!R43 -> 0 | J35: =Formulaire!S43 -> 0 | K35: =Formulaire!T43 -> 0
B36: Acteur17 | C36: =Formulaire!L45 -> 0 | D36: =Formulaire!M45 -> 0 | E36: =Formulaire!N45 -> 0 | F36: =Formulaire!O45 -> 0 | G36: =Formulaire!P45 -> 0 | H36: =Formulaire!Q45 -> 0 | I36: =Formulaire!R45 -> 0 | J36: =Formulaire!S45 -> 0 | K36: =Formulaire!T45 -> 0
B37: Acteur18 | C37: =Formulaire!L47 -> 0 | D37: =Formulaire!M47 -> 0 | E37: =Formulaire!N47 -> 0 | F37: =Formulaire!O47 -> 0 | G37: =Formulaire!P47 -> 0 | H37: =Formulaire!Q47 -> 0 | I37: =Formulaire!R47 -> 0 | J37: =Formulaire!S47 -> 0 | K37: =Formulaire!T47 -> 0
B38: Acteur19 | C38: =Formulaire!L49 -> 0 | D38: =Formulaire!M49 -> 0 | E38: =Formulaire!N49 -> 0 | F38: =Formulaire!O49 -> 0 | G38: =Formulaire!P49 -> 0 | H38: =Formulaire!Q49 -> 0 | I38: =Formulaire!R49 -> 0 | J38: =Formulaire!S49 -> 0 | K38: =Formulaire!T49 -> 0
B39: Acteur20 | C39: =Formulaire!L51 -> 0 | D39: =Formulaire!M51 -> 0 | E39: =Formulaire!N51 -> 0 | F39: =Formulaire!O51 -> 0 | G39: =Formulaire!P51 -> 0 | H39: =Formulaire!Q51 -> 0 | I39: =Formulaire!R51 -> 0 | J39: =Formulaire!S51 -> 0 | K39: =Formulaire!T51 -> 0
B40: Acteur21 | C40: =Formulaire!L53 -> 0 | D40: =Formulaire!M53 -> 0 | E40: =Formulaire!N53 -> 0 | F40: =Formulaire!O53 -> 0 | G40: =Formulaire!P53 -> 0 | H40: =Formulaire!Q53 -> 0 | I40: =Formulaire!R53 -> 0 | J40: =Formulaire!S53 -> 0 | K40: =Formulaire!T53 -> 0
...

Sheet Graphs Implication
C1: IMPLICATION | D1: IMPLICATION | E1: IMPLICATION | F1: IMPLICATION | G1: IMPLICATION | H1: IMPLICATION
B2: N° | C2: 20 | D2: 21 | E2: 22 | F2: 23 | G2: 24 | H2: 25
B3: Indicateur | C3: Nature des liens | D3: Importance des liens | E3: Participation animations | F3: Impression d'être consulté | G3: Qualité des échanges | H3: Evolution des échanges
B4: Définition de la métrique | C4: Evaluation de la nature des liens entre acteurs et RN | D4: Evaluation de l'importance des liens | E4: Evaluation de la participation aux animations | F4: Evaluation du sentiment de consultation sur des sujets qui concernant l'enquêté | G4: Evaluation du ressenti de la qualité des rapports humains avec l'équipe de la RN. | H4: Evaluation de l'évolution des échanges avec l'équipe de la réserve
B5: Question | C5: Pouvez-vous citer tous les liens qui existent entre vous et la réserve ? Et pouvez-vous nous en dire plus leur nature ? | D5: Pouvez-vous qualifier globalement l’importance de ces liens ? | E5: Avez-vous l'habitude de participer à des activités / événements / vernissages / animations / points d'observations… organisées par la RN ? | F5: Vous sentez-vous consulté par la RN sur les sujets qui vous concernent ? | G5: Concernant l’équipe de gestion du site, comment se passent vos échanges ? | H5: Ces échanges ont-ils évolués avec le temps ?
B6: Réponse attendue | C6: Echelle de ressenti | D6: Qualification des liens | E6: Taux de fréquence aux animations | F6: Echelle de ressenti | G6: Echelle de ressenti | H6: Echelle de ressenti
B7: Score 1 | C7: Liens contraints / subis = "RN nous impose un dialogue / une attitude" | D7: Aucun lien | E7: Jamais | F7: Pas du tout | G7: Tension | H7: Evolution négative
B8: Score 2 | C8: x | D8: Liens faibles | E8: <1fois/an | F8: Plutôt non | G8: Aucun échange / insuffisant | H8: x
B9: Score 3 | C9: Liens passifs / opportunistes = échanges ou liens lors de visites ou de contrats | D9: Liens moyens | E9: 1fois/an | F9: Mitigé | G9: Echanges a minima | H9: Pas d'évolution
B10: Score 4 | C10: x | D10: Liens forts | E10: 1fois/trimestre | F10: Plutôt oui | G10: Echanges bienveillants mais peu constructifs | H10: x
B11: Score 5 | C11: Liens forts, guidés par le partage d'une vocation environnementale (recherché par l'acteur) | D11: Liens d'importance prioritaire | E11: 1fois/mois | F11: Tout à fait | G11: Echanges bienveillants et constructifs | H11: Evolution positive
C12: Nature des liens | D12: Participation animations | E12: Ecoute | F12: Echanges | G12: Evolution échanges
B13: MEDIANE Groupe 1 | C13: ='Grille de métriques'!W12 -> #NUM! | D13: ='Grille de métriques'!X12 -> #NUM! | E13: ='Grille de métriques'!Y12 -> #NUM! | F13: ='Grille de métriques'!Z12 -> #NUM! | G13: ='Grille de métriques'!AA12 -> #NUM!
B14: MEDIANE Groupe 2 | C14: ='Grille de métriques'!W20 -> #NUM! | D14: ='Grille de métriques'!X20 -> #NUM! | E14: ='Grille de métriques'!Y20 -> #NUM! | F14: ='Grille de métriques'!Z20 -> #NUM! | G14: ='Grille de métriques'!AA20 -> #NUM!
B15: MEDIANE Groupe 3 | C15: ='Grille de métriques'!W28 -> #NUM! | D15: ='Grille de métriques'!X28 -> #NUM! | E15: ='Grille de métriques'!Y28 -> #NUM! | F15: ='Grille de métriques'!Z28 -> #NUM! | G15: ='Grille de métriques'!AA28 -> #NUM!
B16: MEDIANE Groupe 4 | C16: ='Grille de métriques'!W36 -> #NUM! | D16: ='Grille de métriques'!X36 -> #NUM! | E16: ='Grille de métriques'!Y36 -> #NUM! | F16: ='Grille de métriques'!Z36 -> #NUM! | G16: ='Grille de métriques'!AA36 -> #NUM!
B17: MEDIANE Groupe 5 | C17: ='Grille de métriques'!W44 -> #NUM! | D17: ='Grille de métriques'!X44 -> #NUM! | E17: ='Grille de métriques'!Y44 -> #NUM! | F17: ='Grille de métriques'!Z44 -> #NUM! | G17: ='Grille de métriques'!AA44 -> #NUM!
B18: MEDIANE Tous acteurs | C18: ='Grille de métriques'!W87 -> 0 | D18: ='Grille de métriques'!X87 -> 0 | E18: ='Grille de métriques'!Y87 -> 0 | F18: ='Grille de métriques'!Z87 -> 0 | G18: ='Grille de métriques'!AA87 -> 0
C19: Nature des liens | D19: Participation animations | E19: Ecoute | F19: Echanges | G19: Evolution échanges
B20: Acteur1 | C20: =Formulaire!U13 -> 0 | D20: =Formulaire!V13 -> 0 | E20: =Formulaire!W13 -> 0 | F20: =Formulaire!X13 -> 0 | G20: =Formulaire!Y13 -> 0
B21: Acteur2 | C21: =Formulaire!U15 -> 0 | D21: =Formulaire!V15 -> 0 | E21: =Formulaire!W15 -> 0 | F21: =Formulaire!X15 -> 0 | G21: =Formulaire!Y15 -> 0
B22: Acteur3 | C22: =Formulaire!U17 -> 0 | D22: =Formulaire!V17 -> 0 | E22: =Formulaire!W17 -> 0 | F22: =Formulaire!X17 -> 0 | G22: =Formulaire!Y17 -> 0
B23: Acteur4 | C23: =Formulaire!U19 -> 0 | D23: =Formulaire!V19 -> 0 | E23: =Formulaire!W19 -> 0 | F23: =Formulaire!X19 -> 0 | G23: =Formulaire!Y19 -> 0
B24: Acteur5 | C24: =Formulaire!U21 -> 0 | D24: =Formulaire!V21 -> 0 | E24: =Formulaire!W21 -> 0 | F24: =Formulaire!X21 -> 0 | G24: =Formulaire!Y21 -> 0
B25: Acteur6 | C25: =Formulaire!U23 -> 0 | D25: =Formulaire!V23 -> 0 | E25: =Formulaire!W23 -> 0 | F25: =Formulaire!X23 -> 0 | G25: =Formulaire!Y23 -> 0
B26: Acteur7 | C26: =Formulaire!U25 -> 0 | D26: =Formulaire!V25 -> 0 | E26: =Formulaire!W25 -> 0 | F26: =Formulaire!X25 -> 0 | G26: =Formulaire!Y25 -> 0
B27: Acteur8 | C27: =Formulaire!U27 -> 0 | D27: =Formulaire!V27 -> 0 | E27: =Formulaire!W27 -> 0 | F27: =Formulaire!X27 -> 0 | G27: =Formulaire!Y27 -> 0
B28: Acteur9 | C28: =Formulaire!U29 -> 0 | D28: =Formulaire!V29 -> 0 | E28: =Formulaire!W29 -> 0 | F28: =Formulaire!X29 -> 0 | G28: =Formulaire!Y29 -> 0
B29: Acteur10 | C29: =Formulaire!U31 -> 0 | D29: =Formulaire!V31 -> 0 | E29: =Formulaire!W31 -> 0 | F29: =Formulaire!X31 -> 0 | G29: =Formulaire!Y31 -> 0
B30: Acteur11 | C30: =Formulaire!U33 -> 0 | D30: =Formulaire!V33 -> 0 | E30: =Formulaire!W33 -> 0 | F30: =Formulaire!X33 -> 0 | G30: =Formulaire!Y33 -> 0
B31: Acteur12 | C31: =Formulaire!U35 -> 0 | D31: =Formulaire!V35 -> 0 | E31: =Formulaire!W35 -> 0 | F31: =Formulaire!X35 -> 0 | G31: =Formulaire!Y35 -> 0
B32: Acteur13 | C32: =Formulaire!U37 -> 0 | D32: =Formulaire!V37 -> 0 | E32: =Formulaire!W37 -> 0 | F32: =Formulaire!X37 -> 0 | G32: =Formulaire!Y37 -> 0
B33: Acteur14 | C33: =Formulaire!U39 -> 0 | D33: =Formulaire!V39 -> 0 | E33: =Formulaire!W39 -> 0 | F33: =Formulaire!X39 -> 0 | G33: =Formulaire!Y39 -> 0
B34: Acteur15 | C34: =Formulaire!U41 -> 0 | D34: =Formulaire!V41 -> 0 | E34: =Formulaire!W41 -> 0 | F34: =Formulaire!X41 -> 0 | G34: =Formulaire!Y41 -> 0
B35: Acteur16 | C35: =Formulaire!U43 -> 0 | D35: =Formulaire!V43 -> 0 | E35: =Formulaire!W43 -> 0 | F35: =Formulaire!X43 -> 0 | G35: =Formulaire!Y43 -> 0
B36: Acteur17 | C36: =Formulaire!U45 -> 0 | D36: =Formulaire!V45 -> 0 | E36: =Formulaire!W45 -> 0 | F36: =Formulaire!X45 -> 0 | G36: =Formulaire!Y45 -> 0
B37: Acteur18 | C37: =Formulaire!U47 -> 0 | D37: =Formulaire!V47 -> 0 | E37: =Formulaire!W47 -> 0 | F37: =Formulaire!X47 -> 0 | G37: =Formulaire!Y47 -> 0
B38: Acteur19 | C38: =Formulaire!U49 -> 0 | D38: =Formulaire!V49 -> 0 | E38: =Formulaire!W49 -> 0 | F38: =Formulaire!X49 -> 0 | G38: =Formulaire!Y49 -> 0
B39: Acteur20 | C39: =Formulaire!U51 -> 0 | D39: =Formulaire!V51 -> 0 | E39: =Formulaire!W51 -> 0 | F39: =Formulaire!X51 -> 0 | G39: =Formulaire!Y51 -> 0
B40: Acteur21 | C40: =Formulaire!U53 -> 0 | D40: =Formulaire!V53 -> 0 | E40: =Formulaire!W53 -> 0 | F40: =Formulaire!X53 -> 0 | G40: =Formulaire!Y53 -> 0
...

Sheet AFOM
B1: Analyse AFOM : occurrences de toutes les réponses (recoupements des mots clés par thématiques)
B2: Atouts | C2: Occurences | D2: Faiblesses | E2: Occurences
B3: passion | C3: 20 | D3: communication | E3: 10
B4: dynamisme | C4: 15 | D4: …
B5: ecoute | C5: 10
B6: animations | C6: 5
B7: …
B12: Opportunités | C12: Occurences | D12: Menaces | E12: Occurences
B13: patrenariat CommComm | C13: 5 | D13: Montée des eaux | E13: 15
B14: … | D14: …
B36: Document mis à disposition sous un contrat Creative Commons CC BY-NC-ND (4.0) https://creativecommons.org/licenses/by-nc-nd/4.0/

Sheet CCG
A1: Evaluation de la gouvernance - METRIQUES HORS DAT
A2: Spécifique aux membres du CCG | B2: métrique complémentaire : CCG
A3: analyse complémentaire | B3: 26 | C3: 27 | D3: 28 | E3: 29
B4: Implication CCG | C4: Avis CCG | D4: Interventions CCG | E4: Participation CCG
B5: Evaluation du sentiment d'implication | C5: Ressenti d'intérêt vis-à-vis de cette instance | D5: Evaluation de la fréquence d'interventions | E5: Evaluation de la fréquence de participation
B6: En tant que membre du CCG, avez-vous l'impression d'être impliqué dans la vie de la RN | C6: Que pensez-vous du CCG, en tant qu’instance de discussion ? | D6: Lors du CCG, faites-vous des interventions régulièrement (questions, prises de positions) | E6: Quelle est la fréquence de votre participation au CCG ?
B7: Echelle de ressenti | C7: Echelle de ressenti | D7: Echelle de ressenti | E7: Echelle de ressenti
B8: Pas du tout | C8: Non intérêt | D8: Jamais | E8: Jamais
B9: Plutôt non | C9: Criticable | D9: Rarement | E9: 1x sur les 5 dernières années
B10: Mitigé | C10: Pas d'avis | D10: De temps en temps | E10: 2x sur les 5 dernières années
B11: Plutôt oui | C11: Correct | D11: La plupart du temps | E11: 3x sur les 5 dernières années
B12: Tout à fait | C12: Efficace et légitime | D12: Toujours | E12: 4x ou > sur les 5 dernières années
A13: MEDIANE Groupe 1 | B13: ='Grille de métriques'!AB12 -> #NUM! | C13: ='Grille de métriques'!AC12 -> #NUM! | D13: ='Grille de métriques'!AD12 -> #NUM! | E13: ='Grille de métriques'!AE12 -> #NUM!
A14: MEDIANE Groupe 2 | B14: ='Grille de métriques'!AB20 -> #NUM! | C14: ='Grille de métriques'!AC20 -> #NUM! | D14: ='Grille de métriques'!AD20 -> #NUM! | E14: ='Grille de métriques'!AE20 -> #NUM!
A15: MEDIANE Groupe 3 | B15: ='Grille de métriques'!AB28 -> #NUM! | C15: ='Grille de métriques'!AC28 -> #NUM! | D15: ='Grille de métriques'!AD28 -> #NUM! | E15: ='Grille de métriques'!AE28 -> #NUM!
A16: MEDIANE Groupe 4 | B16: ='Grille de métriques'!AB36 -> #NUM! | C16: ='Grille de métriques'!AC36 -> #NUM! | D16: ='Grille de métriques'!AD36 -> #NUM! | E16: ='Grille de métriques'!AE36 -> #NUM!
A17: MEDIANE Groupe 5 | B17: ='Grille de métriques'!AB44 -> #NUM! | C17: ='Grille de métriques'!AC44 -> #NUM! | D17: ='Grille de métriques'!AD44 -> #NUM! | E17: ='Grille de métriques'!AE44 -> #NUM!
